Workbook

Sheet Requests
A1: Request ID | B1: Course Title | C1: Instructor | D1: Submitted Date | E1: Delivery Method | F1: Duration (min) | G1: Field of Study | H1: Program Level | I1: Learning Objectives | J1: Attendance Checks | K1: Review Questions | L1: Prerequisites | M1: SLA Due Date | N1: Reviewer | O1: Status
A2: CPE-2026-001 | B2: Mastering Blockchain in Accounting | C2: Karen Li | D2: 46279 | E2: Self-study | F2: 140 | G2: Economics | H2: Basic | I2: 9 | J2: 0 | K2: 8 | L2: N | M2: 46284 | N2: CPE Desk - Omar | O2: Approved
A3: CPE-2026-002 | B3: Mastering Blockchain in Accounting | C3: Karen Li | D3: 46282 | E3: Self-study | F3: 140 | G3: Management | H3: Basic | I3: 9 | J3: 0 | K3: 8 | L3: Y | M3: 46287 | N3: CPE Desk - Luis | O3: Approved
A4: CPE-2026-003 | B4: Introduction to Tax Reform | C4: Elena Voss | D4: 46306 | E4: Group | F4: 150 | G4: Specialized Knowledge | H4: Basic | I4: 9 | J4: 9 | K4: 0 | L4: N | M4: 46311 | N4: CPE Desk - Luis | O4: Approved
A5: CPE-2026-004 | B5: Current Issues in Internal Controls | C5: Quinn Torres | D5: 46282 | E5: Group | F5: 45 | G5: Business Law | H5: Intermediate | I5: 1 | J5: 3 | K5: 0 | L5: N | M5: 46287 | N5: CPE Desk - Priya | O5: Needs Correction
A6: CPE-2026-005 | B6: Workshop: Data Analytics for CPAs | C6: Olivia Chen | D6: 46266 | E6: Self-study | F6: 50 | G6: Business Law | H6: Basic | I6: 3 | J6: 0 | K6: 3 | L6: N | M6: 46271 | N6: CPE Desk - Omar | O6: Approved
A7: CPE-2026-006 | B7: Practical International Tax | C7: Frank Huang | D7: 46300 | E7: Group | F7: 110 | G7: Economics | H7: Basic | I7: 7 | J7: 7 | K7: 0 | L7: Y | M7: 46305 | N7: CPE Desk - Sarah | O7: Approved
A8: CPE-2026-007 | B8: Essentials of Ethical Decision Making | C8: Ben Tanaka | D8: 46281 | E8: Group | F8: 30 | G8: Economics | H8: Basic | I8: 0 | J8: 2 | K8: 0 | L8: Y | M8: 46286 | N8: CPE Desk - Omar | O8: Needs Correction
A9: CPE-2026-008 | B9: Seminar: Financial Modeling | C9: Frank Huang | D9: 46282 | E9: Self-study | F9: 60 | G9: Business Law | H9: Advanced | I9: 4 | J9: 0 | K9: 3 | L9: Y | M9: 46287 | N9: CPE Desk - Sarah | O9: Approved
A10: CPE-2026-009 | B10: Workshop: International Tax | C10: Olivia Chen | D10: 46323 | E10: Self-study | F10: 45 | G10: Finance | H10: Basic | I10: 3 | J10: 0 | K10: 2 | L10: Y | M10: 46328 | N10: CPE Desk - Sarah | O10: Pending
A11: CPE-2026-010 | B11: Introduction to Blockchain in Accounting | C11: Rachel Novak | D11: 46280 | E11: Group | F11: 20 | G11: Auditing | H11: Advanced | I11: 2 | J11: 2 | K11: 0 | L11: Y | M11: 46285 | N11: CPE Desk - Omar | O11: Approved
A12: CPE-2026-011 | B12: Advanced Revenue Recognition | C12: Karen Li | D12: 46270 | E12: Group | F12: 90 | G12: Economics | H12: Basic | I12: 6 | J12: 6 | K12: 0 | L12: Y | M12: 46275 | N12: CPE Desk - Luis | O12: Approved
A13: CPE-2026-012 | B13: Mastering SOX Compliance | C13: Nate Johansson | D13: 46278 | E13: Group | F13: 45 | G13: Information Technology | H13: Intermediate | I13: 1 | J13: 3 | K13: 0 | L13: N | M13: 46283 | N13: CPE Desk - Luis | O13: Needs Correction
... A20: CPE-2026-019 | B20: Current Issues in Lease Accounting | C20: Henry Reyes | D20: 46291 | E20: Group | F20: 75 | G20: Specialized Knowledge | H20: Advanced | I20: 5 | J20: 5 | K20: 0 | L20: Y | M20: 46296 | N20: CPE Desk - Priya | O20: Approved
A21: CPE-2026-020 | B21: Workshop: Blockchain in Accounting | C21: Sam Adeyemi | D21: 46299 | E21: Self-study | F21: 90 | H21: Advanced | I21: 6 | J21: 0 | K21: 5 | L21: N | M21: 46304 | N21: CPE Desk - Omar | O21: Escalate
A22: CPE-2026-021 | B22: Essentials of QuickBooks Pro | C22: Elena Voss | D22: 46308 | E22: Self-study | F22: 170 | G22: Management | H22: Basic | I22: 11 | J22: 0 | K22: 9 | L22: Y | M22: 46313 | N22: CPE Desk - Luis | O22: Needs Correction
A23: CPE-2026-022 | B23: Advanced Financial Modeling | C23: Grace Patel | D23: 46298 | E23: Self-study | F23: 49 | G23: Management | H23: Basic | I23: 3 | J23: 0 | K23: 2 | L23: Y | M23: 46303 | N23: CPE Desk - Sarah | O23: Needs Correction
A24: CPE-2026-023 | B24: Essentials of Data Analytics for CPAs | C24: Olivia Chen | D24: 46319 | E24: Self-study | F24: 35 | G24: Business Law | H24: Intermediate | I24: 2 | J24: 0 | K24: 2 | L24: Y | M24: 46324 | N24: CPE Desk - Omar | O24: Pending
A25: CPE-2026-024 | B25: Advanced Tax Reform | C25: Rachel Novak | D25: 46275 | E25: Self-study | F25: 100 | G25: Specialized Knowledge | H25: Basic | I25: 6 | J25: 0 | K25: 6 | L25: N | M25: 46280 | N25: CPE Desk - Omar | O25: Approved
A26: CPE-2026-025 | B26: Essentials of IFRS vs GAAP | C26: Paul Mbeki | D26: 46282 | E26: Group | F26: 30 | G26: Information Technology | H26: Intermediate | I26: 2 | J26: 2 | K26: 0 | L26: Y | M26: 46287 | N26: CPE Desk - Priya | O26: Approved
A27: CPE-2026-026 | B27: Deep Dive into Cybersecurity Risk | C27: Irene Schultz | D27: 46276 | E27: Self-study | F27: 150 | G27: Business Law | H27: Basic | I27: 9 | J27: 0 | K27: 9 | L27: Y | M27: 46281 | N27: CPE Desk - Priya | O27: Approved
A28: CPE-2026-027 | B28: Practical Financial Modeling | C28: Ben Tanaka | D28: 46319 | E28: Self-study | F28: 49 | G28: Information Technology | H28: Basic | I28: 3 | J28: 0 | K28: 2 | L28: Y | M28: 46324 | N28: CPE Desk - Sarah | O28: Pending
A29: CPE-2026-028 | B29: Deep Dive into Revenue Recognition | C29: Leo Fernandez | D29: 46279 | E29: Group | F29: 55 | G29: Management | H29: Advanced | I29: 3 | J29: 3 | K29: 0 | L29: N | M29: 46284 | N29: CPE Desk - Omar | O29: Needs Correction
A30: CPE-2026-029 | B30: Practical Data Analytics for CPAs | C30: Nate Johansson | D30: 46267 | E30: Group | F30: 110 | G30: Information Technology | H30: Advanced | I30: 7 | J30: 7 | K30: 0 | L30: Y | M30: 46272 | N30: CPE Desk - Sarah | O30: Approved
A31: CPE-2026-030 | B31: Practical Tax Reform | C31: Maya Brooks | D31: 46321 | E31: Group | F31: 200 | H31: Basic | I31: 12 | J31: 12 | K31: 0 | L31: N | M31: 46326 | N31: CPE Desk - Sarah | O31: Pending
A32: CPE-2026-031 | B32: Essentials of Ethical Decision Making | C32: Henry Reyes | D32: 46267 | E32: Group | F32: 140 | G32: Management | H32: Intermediate | I32: 7 | J32: 9 | K32: 0 | L32: Y | M32: 46272 | N32: CPE Desk - Sarah | O32: Needs Correction
A33: CPE-2026-032 | B33: Foundations of QuickBooks Pro | C33: Rachel Novak | D33: 46287 | E33: Group | F33: 45 | G33: Ethics | H33: Basic | I33: 3 | J33: 3 | K33: 0 | L33: N | M33: 46292 | N33: CPE Desk - Priya | O33: Approved
A34: CPE-2026-033 | B34: Advanced Remote Audit Techniques | C34: Nate Johansson | D34: 46288 | E34: Self-study | F34: 150 | G34: Specialized Knowledge | H34: Advanced | I34: 9 | J34: 0 | K34: 9 | L34: Y | M34: 46293 | N34: CPE Desk - Luis | O34: Approved
A35: CPE-2026-034 | B35: Current Issues in Fraud Prevention | C35: Irene Schultz | D35: 46268 | E35: Self-study | F35: 20 | G35: Business Law | H35: Advanced | I35: 2 | J35: 0 | K35: 1 | L35: Y | M35: 46273 | N35: CPE Desk - Sarah | O35: Approved
A36: CPE-2026-035 | B36: Workshop: Lease Accounting | C36: Karen Li | D36: 46305 | E36: Self-study | F36: 45 | G36: Ethics | H36: Advanced | I36: 3 | J36: 0 | K36: 2 | L36: N | M36: 46310 | N36: CPE Desk - Luis | O36: Approved
A37: CPE-2026-036 | B37: Deep Dive into QuickBooks Pro | C37: James Osei | D37: 46301 | E37: Group | F37: 60 | G37: Information Technology | H37: Advanced | I37: 4 | J37: 4 | K37: 0 | L37: N | M37: 46306 | N37: CPE Desk - Omar | O37: Approved
A38: CPE-2026-037 | B38: Current Issues in Blockchain in Accounting | C38: James Osei | D38: 46291 | E38: Group | F38: 100 | G38: Ethics | H38: Basic | I38: 6 | J38: 6 | K38: 0 | L38: N | M38: 46296 | N38: CPE Desk - Sarah | O38: Approved
A39: CPE-2026-038 | B39: Seminar: Internal Controls | C39: Olivia Chen | D39: 46309 | E39: Group | F39: 200 | G39: Taxation | H39: Advanced | I39: 12 | J39: 12 | K39: 0 | L39: Y | M39: 46314 | N39: CPE Desk - Sarah | O39: Approved
A40: CPE-2026-039 | B40: Foundations of Remote Audit Techniques | C40: Karen Li | D40: 46271 | E40: Group | F40: 100 | G40: Finance | H40: Basic | I40: 6 | J40: 6 | K40: 0 | L40: Y | M40: 46276 | N40: CPE Desk - Priya | O40: Approved
A41: CPE-2026-040 | B41: Introduction to Ethical Decision Making | C41: Paul Mbeki | D41: 46305 | E41: Group | F41: 180 | G41: Information Technology | H41: Advanced | I41: 9 | J41: 11 | K41: 0 | L41: Y | M41: 46310 | N41: CPE Desk - Luis | O41: Needs Correction
A42: CPE-2026-041 | B42: Workshop: Ethical Decision Making | C42: Elena Voss | D42: 46307 | E42: Group | F42: 45 | H42: Basic | I42: 3 | J42: 3 | K42: 0 | L42: Y | M42: 46312 | N42: CPE Desk - Luis | O42: Escalate
A43: CPE-2026-042 | B43: Introduction to Financial Modeling | C43: Henry Reyes | D43: 46320 | E43: Group | F43: 180 | G43: Taxation | H43: Intermediate | I43: 11 | J43: 0 | K43: 0 | L43: N | M43: 46325 | N43: CPE Desk - Luis | O43: Pending
A44: CPE-2026-043 | B44: Introduction to Financial Modeling | C44: Henry Reyes | D44: 46319 | E44: Self-study | F44: 50 | G44: Economics | H44: Intermediate | I44: 3 | J44: 0 | K44: 3 | L44: N | M44: 46324 | N44: CPE Desk - Omar | O44: Pending
A45: CPE-2026-044 | B45: Current Issues in Lease Accounting | C45: Henry Reyes | D45: 46306 | E45: Group | F45: 90 | G45: Economics | H45: Basic | I45: 6 | J45: 6 | K45: 0 | L45: N | M45: 46311 | N45: CPE Desk - Omar | O45: Approved
A46: CPE-2026-045 | B46: Deep Dive into Estate Planning | C46: Rachel Novak | D46: 46271 | E46: Group | F46: 49 | G46: Finance | H46: Intermediate | I46: 3 | J46: 0 | K46: 0 | L46: Y | M46: 46276 | N46: CPE Desk - Omar | O46: Needs Correction
...

Sheet Rules
A1: Label | B1: Parameter | C1: Value | D1: Unit | E1: Source | F1: Note
A2: NASBA-Style Rules – Editable Parameters
A4: LEARNING OBJECTIVES
A5: Minimum objectives per 50 min | B5: MIN_OBJ_PER_50 | C5: 3 | D5: per 50 min | E5: IASA / NASBA | F5: 3 objectives per 50-minute credit hour
A6: Minimum duration to award any credit | B6: MIN_DURATION_MIN | C6: 25 | D6: minutes | E6: NASBA | F6: < 25 min = 0 credits
A8: ATTENDANCE & ENGAGEMENT (Group)
A9: Min attendance checks per 50-min hour (Group-live tech) | B9: MIN_ATT_PER_50 | C9: 3 | D9: per 50 min | E9: LearnSignal / NASBA | F9: Three checks per credit hour
A11: SELF-STUDY
A12: Min review questions per credit hour (Self-study) | B12: MIN_RQ_PER_CREDIT | C12: 3 | D12: per credit | E12: NASBA SS Standard | F12: Verify against current NASBA self-study standard
A14: CREDIT ROUNDING
A15: Half-credit increment (Group programs) | B15: CREDIT_INCREMENT | C15: 0.5 | D15: credits | E15: NASBA | F15: FLOOR(min/50, 0.5)
A16: Fifth-credit increment (alt rounding) | B16: CREDIT_INCREMENT_5TH | C16: 0.2 | D16: credits | E16: NASBA alt | F16: ROUNDDOWN(min/50*5,0)/5
A18: REQUIRED FIELDS
A19: Field of Study required | B19: FOS_REQUIRED | C19: Y | D19: — | E19: NASBA | F19: Must not be blank
A20: Program Level required | B20: LEVEL_REQUIRED | C20: Y | D20: — | E20: NASBA | F20: Basic / Intermediate / Advanced
A21: Delivery Method required | B21: METHOD_REQUIRED | C21: Y | D21: — | E21: NASBA | F21: Group or Self-study
A22: Prerequisites documented | B22: PREREQ_REQUIRED | C22: Y | D22: — | E22: NASBA | F22: Y or N must be stated
A24: SLA
A25: SLA turnaround days | B25: SLA_DAYS | C25: 5 | D25: business days | E25: Firm policy | F25: Submitted date + 5 days
A26: Due-soon warning threshold | B26: DUE_SOON_DAYS | C26: 1 | D26: days | E26: Firm policy | F26: Amber flag within 1 day

Sheet Review
A1: Request ID | B1: Course Title | C1: Duration (min) | D1: Delivery Method | E1: Learning Objectives | F1: Min Obj Needed | G1: Obj Check | H1: Attendance Checks | I1: Min Att Needed | J1: Att Check | K1: Field of Study | L1: FOS Check | M1: Program Level | N1: Level Check | O1: Review Questions | P1: RQ Check | Q1: Credits (Half) | R1: Credits (Fifth) | S1: SLA Flag | T1: Decision | U1: Reason
A2: =Requests!A2 | B2: =Requests!B2 | C2: =Requests!F2 | D2: =Requests!E2 | E2: =Requests!I2 | F2: =ROUNDUP(C2/50*Rules!$C$5,0) | G2: =IF(E2>=F2,"Pass","Fail") | H2: =Requests!J2 | I2: =IF(D2="Group",ROUNDUP(C2/50*Rules!$C$9,0),0) | J2: =IF(D2="Self-study","N/A",IF(H2>=I2,"Pass","Fail")) | K2: =Requests!G2 | L2: =IF(K2<>"","Pass","Fail – Missing FOS") | M2: =Requests!H2 | N2: =IF(OR(M2="Basic",M2="Intermediate",M2="Advanced"),"Pass","Fail") | O2: =Requests!K2 | P2: =IF(D2="Self-study",IF(O2>=ROUNDUP(Q2*Rules!$C$12,0),"Pass","Fail"),"N/A") | Q2: =IF(C2<25,0,FLOOR(C2/50,0.5)) | R2: =IF(C2<50,0,ROUNDDOWN(C2/50*5,0)/5) | S2: =IF(AND(Requests!O2<>"Approved",Requests!M2<TODAY()),"Overdue",IF(Requests!M2-TODAY()<=Rules!$C$26,"Due Soon","On Track")) | T2: =IF(AND(G2="Pass",J2<>"Fail",L2="Pass",N2="Pass",P2<>"Fail"),"Approved",IF(OR(L2="Fail – Missing FOS",N2="Fail"),"Escalate","Needs Correction")) | U2: =IFERROR(IF(G2<>"Pass","Insufficient learning objectives; ","")&IF(AND(J2="Fail",D2="Group"),"Missing attendance checks; ","")&IF(L2<>"Pass","Missing field of study; ","")&IF(N2<>"Pass","Invalid program level; ","")&IF(AND(P2="Fail",D2="Self-study"),"Insufficient review questions; ",""),"Check data")
A3: =Requests!A3 | B3: =Requests!B3 | C3: =Requests!F3 | D3: =Requests!E3 | E3: =Requests!I3 | F3: =ROUNDUP(C3/50*Rules!$C$5,0) | G3: =IF(E3>=F3,"Pass","Fail") | H3: =Requests!J3 | I3: =IF(D3="Group",ROUNDUP(C3/50*Rules!$C$9,0),0) | J3: =IF(D3="Self-study","N/A",IF(H3>=I3,"Pass","Fail")) | K3: =Requests!G3 | L3: =IF(K3<>"","Pass","Fail – Missing FOS") | M3: =Requests!H3 | N3: =IF(OR(M3="Basic",M3="Intermediate",M3="Advanced"),"Pass","Fail") | O3: =Requests!K3 | P3: =IF(D3="Self-study",IF(O3>=ROUNDUP(Q3*Rules!$C$12,0),"Pass","Fail"),"N/A") | Q3: =IF(C3<25,0,FLOOR(C3/50,0.5)) | R3: =IF(C3<50,0,ROUNDDOWN(C3/50*5,0)/5) | S3: =IF(AND(Requests!O3<>"Approved",Requests!M3<TODAY()),"Overdue",IF(Requests!M3-TODAY()<=Rules!$C$26,"Due Soon","On Track")) | T3: =IF(AND(G3="Pass",J3<>"Fail",L3="Pass",N3="Pass",P3<>"Fail"),"Approved",IF(OR(L3="Fail – Missing FOS",N3="Fail"),"Escalate","Needs Correction")) | U3: =IFERROR(IF(G3<>"Pass","Insufficient learning objectives; ","")&IF(AND(J3="Fail",D3="Group"),"Missing attendance checks; ","")&IF(L3<>"Pass","Missing field of study; ","")&IF(N3<>"Pass","Invalid program level; ","")&IF(AND(P3="Fail",D3="Self-study"),"Insufficient review questions; ",""),"Check data")
A4: =Requests!A4 | B4: =Requests!B4 | C4: =Requests!F4 | D4: =Requests!E4 | E4: =Requests!I4 | F4: =ROUNDUP(C4/50*Rules!$C$5,0) | G4: =IF(E4>=F4,"Pass","Fail") | H4: =Requests!J4 | I4: =IF(D4="Group",ROUNDUP(C4/50*Rules!$C$9,0),0) | J4: =IF(D4="Self-study","N/A",IF(H4>=I4,"Pass","Fail")) | K4: =Requests!G4 | L4: =IF(K4<>"","Pass","Fail – Missing FOS") | M4: =Requests!H4 | N4: =IF(OR(M4="Basic",M4="Intermediate",M4="Advanced"),"Pass","Fail") | O4: =Requests!K4 | P4: =IF(D4="Self-study",IF(O4>=ROUNDUP(Q4*Rules!$C$12,0),"Pass","Fail"),"N/A") | Q4: =IF(C4<25,0,FLOOR(C4/50,0.5)) | R4: =IF(C4<50,0,ROUNDDOWN(C4/50*5,0)/5) | S4: =IF(AND(Requests!O4<>"Approved",Requests!M4<TODAY()),"Overdue",IF(Requests!M4-TODAY()<=Rules!$C$26,"Due Soon","On Track")) | T4: =IF(AND(G4="Pass",J4<>"Fail",L4="Pass",N4="Pass",P4<>"Fail"),"Approved",IF(OR(L4="Fail – Missing FOS",N4="Fail"),"Escalate","Needs Correction")) | U4: =IFERROR(IF(G4<>"Pass","Insufficient learning objectives; ","")&IF(AND(J4="Fail",D4="Group"),"Missing attendance checks; ","")&IF(L4<>"Pass","Missing field of study; ","")&IF(N4<>"Pass","Invalid program level; ","")&IF(AND(P4="Fail",D4="Self-study"),"Insufficient review questions; ",""),"Check data")
A5: =Requests!A5 | B5: =Requests!B5 | C5: =Requests!F5 | D5: =Requests!E5 | E5: =Requests!I5 | F5: =ROUNDUP(C5/50*Rules!$C$5,0) | G5: =IF(E5>=F5,"Pass","Fail") | H5: =Requests!J5 | I5: =IF(D5="Group",ROUNDUP(C5/50*Rules!$C$9,0),0) | J5: =IF(D5="Self-study","N/A",IF(H5>=I5,"Pass","Fail")) | K5: =Requests!G5 | L5: =IF(K5<>"","Pass","Fail – Missing FOS") | M5: =Requests!H5 | N5: =IF(OR(M5="Basic",M5="Intermediate",M5="Advanced"),"Pass","Fail") | O5: =Requests!K5 | P5: =IF(D5="Self-study",IF(O5>=ROUNDUP(Q5*Rules!$C$12,0),"Pass","Fail"),"N/A") | Q5: =IF(C5<25,0,FLOOR(C5/50,0.5)) | R5: =IF(C5<50,0,ROUNDDOWN(C5/50*5,0)/5) | S5: =IF(AND(Requests!O5<>"Approved",Requests!M5<TODAY()),"Overdue",IF(Requests!M5-TODAY()<=Rules!$C$26,"Due Soon","On Track")) | T5: =IF(AND(G5="Pass",J5<>"Fail",L5="Pass",N5="Pass",P5<>"Fail"),"Approved",IF(OR(L5="Fail – Missing FOS",N5="Fail"),"Escalate","Needs Correction")) | U5: =IFERROR(IF(G5<>"Pass","Insufficient learning objectives; ","")&IF(AND(J5="Fail",D5="Group"),"Missing attendance checks; ","")&IF(L5<>"Pass","Missing field of study; ","")&IF(N5<>"Pass","Invalid program level; ","")&IF(AND(P5="Fail",D5="Self-study"),"Insufficient review questions; ",""),"Check data")
A6: =Requests!A6 | B6: =Requests!B6 | C6: =Requests!F6 | D6: =Requests!E6 | E6: =Requests!I6 | F6: =ROUNDUP(C6/50*Rules!$C$5,0) | G6: =IF(E6>=F6,"Pass","Fail") | H6: =Requests!J6 | I6: =IF(D6="Group",ROUNDUP(C6/50*Rules!$C$9,0),0) | J6: =IF(D6="Self-study","N/A",IF(H6>=I6,"Pass","Fail")) | K6: =Requests!G6 | L6: =IF(K6<>"","Pass","Fail – Missing FOS") | M6: =Requests!H6 | N6: =IF(OR(M6="Basic",M6="Intermediate",M6="Advanced"),"Pass","Fail") | O6: =Requests!K6 | P6: =IF(D6="Self-study",IF(O6>=ROUNDUP(Q6*Rules!$C$12,0),"Pass","Fail"),"N/A") | Q6: =IF(C6<25,0,FLOOR(C6/50,0.5)) | R6: =IF(C6<50,0,ROUNDDOWN(C6/50*5,0)/5) | S6: =IF(AND(Requests!O6<>"Approved",Requests!M6<TODAY()),"Overdue",IF(Requests!M6-TODAY()<=Rules!$C$26,"Due Soon","On Track")) | T6: =IF(AND(G6="Pass",J6<>"Fail",L6="Pass",N6="Pass",P6<>"Fail"),"Approved",IF(OR(L6="Fail – Missing FOS",N6="Fail"),"Escalate","Needs Correction")) | U6: =IFERROR(IF(G6<>"Pass","Insufficient learning objectives; ","")&IF(AND(J6="Fail",D6="Group"),"Missing attendance checks; ","")&IF(L6<>"Pass","Missing field of study; ","")&IF(N6<>"Pass","Invalid program level; ","")&IF(AND(P6="Fail",D6="Self-study"),"Insufficient review questions; ",""),"Check data")
A7: =Requests!A7 | B7: =Requests!B7 | C7: =Requests!F7 | D7: =Requests!E7 | E7: =Requests!I7 | F7: =ROUNDUP(C7/50*Rules!$C$5,0) | G7: =IF(E7>=F7,"Pass","Fail") | H7: =Requests!J7 | I7: =IF(D7="Group",ROUNDUP(C7/50*Rules!$C$9,0),0) | J7: =IF(D7="Self-study","N/A",IF(H7>=I7,"Pass","Fail")) | K7: =Requests!G7 | L7: =IF(K7<>"","Pass","Fail – Missing FOS") | M7: =Requests!H7 | N7: =IF(OR(M7="Basic",M7="Intermediate",M7="Advanced"),"Pass","Fail") | O7: =Requests!K7 | P7: =IF(D7="Self-study",IF(O7>=ROUNDUP(Q7*Rules!$C$12,0),"Pass","Fail"),"N/A") | Q7: =IF(C7<25,0,FLOOR(C7/50,0.5)) | R7: =IF(C7<50,0,ROUNDDOWN(C7/50*5,0)/5) | S7: =IF(AND(Requests!O7<>"Approved",Requests!M7<TODAY()),"Overdue",IF(Requests!M7-TODAY()<=Rules!$C$26,"Due Soon","On Track")) | T7: =IF(AND(G7="Pass",J7<>"Fail",L7="Pass",N7="Pass",P7<>"Fail"),"Approved",IF(OR(L7="Fail – Missing FOS",N7="Fail"),"Escalate","Needs Correction")) | U7: =IFERROR(IF(G7<>"Pass","Insufficient learning objectives; ","")&IF(AND(J7="Fail",D7="Group"),"Missing attendance checks; ","")&IF(L7<>"Pass","Missing field of study; ","")&IF(N7<>"Pass","Invalid program level; ","")&IF(AND(P7="Fail",D7="Self-study"),"Insufficient review questions; ",""),"Check data")
A8: =Requests!A8 | B8: =Requests!B8 | C8: =Requests!F8 | D8: =Requests!E8 | E8: =Requests!I8 | F8: =ROUNDUP(C8/50*Rules!$C$5,0) | G8: =IF(E8>=F8,"Pass","Fail") | H8: =Requests!J8 | I8: =IF(D8="Group",ROUNDUP(C8/50*Rules!$C$9,0),0) | J8: =IF(D8="Self-study","N/A",IF(H8>=I8,"Pass","Fail")) | K8: =Requests!G8 | L8: =IF(K8<>"","Pass","Fail – Missing FOS") | M8: =Requests!H8 | N8: =IF(OR(M8="Basic",M8="Intermediate",M8="Advanced"),"Pass","Fail") | O8: =Requests!K8 | P8: =IF(D8="Self-study",IF(O8>=ROUNDUP(Q8*Rules!$C$12,0),"Pass","Fail"),"N/A") | Q8: =IF(C8<25,0,FLOOR(C8/50,0.5)) | R8: =IF(C8<50,0,ROUNDDOWN(C8/50*5,0)/5) | S8: =IF(AND(Requests!O8<>"Approved",Requests!M8<TODAY()),"Overdue",IF(Requests!M8-TODAY()<=Rules!$C$26,"Due Soon","On Track")) | T8: =IF(AND(G8="Pass",J8<>"Fail",L8="Pass",N8="Pass",P8<>"Fail"),"Approved",IF(OR(L8="Fail – Missing FOS",N8="Fail"),"Escalate","Needs Correction")) | U8: =IFERROR(IF(G8<>"Pass","Insufficient learning objectives; ","")&IF(AND(J8="Fail",D8="Group"),"Missing attendance checks; ","")&IF(L8<>"Pass","Missing field of study; ","")&IF(N8<>"Pass","Invalid program level; ","")&IF(AND(P8="Fail",D8="Self-study"),"Insufficient review questions; ",""),"Check data")
A9: =Requests!A9 | B9: =Requests!B9 | C9: =Requests!F9 | D9: =Requests!E9 | E9: =Requests!I9 | F9: =ROUNDUP(C9/50*Rules!$C$5,0) | G9: =IF(E9>=F9,"Pass","Fail") | H9: =Requests!J9 | I9: =IF(D9="Group",ROUNDUP(C9/50*Rules!$C$9,0),0) | J9: =IF(D9="Self-study","N/A",IF(H9>=I9,"Pass","Fail")) | K9: =Requests!G9 | L9: =IF(K9<>"","Pass","Fail – Missing FOS") | M9: =Requests!H9 | N9: =IF(OR(M9="Basic",M9="Intermediate",M9="Advanced"),"Pass","Fail") | O9: =Requests!K9 | P9: =IF(D9="Self-study",IF(O9>=ROUNDUP(Q9*Rules!$C$12,0),"Pass","Fail"),"N/A") | Q9: =IF(C9<25,0,FLOOR(C9/50,0.5)) | R9: =IF(C9<50,0,ROUNDDOWN(C9/50*5,0)/5) | S9: =IF(AND(Requests!O9<>"Approved",Requests!M9<TODAY()),"Overdue",IF(Requests!M9-TODAY()<=Rules!$C$26,"Due Soon","On Track")) | T9: =IF(AND(G9="Pass",J9<>"Fail",L9="Pass",N9="Pass",P9<>"Fail"),"Approved",IF(OR(L9="Fail – Missing FOS",N9="Fail"),"Escalate","Needs Correction")) | U9: =IFERROR(IF(G9<>"Pass","Insufficient learning objectives; ","")&IF(AND(J9="Fail",D9="Group"),"Missing attendance checks; ","")&IF(L9<>"Pass","Missing field of study; ","")&IF(N9<>"Pass","Invalid program level; ","")&IF(AND(P9="Fail",D9="Self-study"),"Insufficient review questions; ",""),"Check data")
A10: =Requests!A10 | B10: =Requests!B10 | C10: =Requests!F10 | D10: =Requests!E10 | E10: =Requests!I10 | F10: =ROUNDUP(C10/50*Rules!$C$5,0) | G10: =IF(E10>=F10,"Pass","Fail") | H10: =Requests!J10 | I10: =IF(D10="Group",ROUNDUP(C10/50*Rules!$C$9,0),0) | J10: =IF(D10="Self-study","N/A",IF(H10>=I10,"Pass","Fail")) | K10: =Requests!G10 | L10: =IF(K10<>"","Pass","Fail – Missing FOS") | M10: =Requests!H10 | N10: =IF(OR(M10="Basic",M10="Intermediate",M10="Advanced"),"Pass","Fail") | O10: =Requests!K10 | P10: =IF(D10="Self-study",IF(O10>=ROUNDUP(Q10*Rules!$C$12,0),"Pass","Fail"),"N/A") | Q10: =IF(C10<25,0,FLOOR(C10/50,0.5)) | R10: =IF(C10<50,0,ROUNDDOWN(C10/50*5,0)/5) | S10: =IF(AND(Requests!O10<>"Approved",Requests!M10<TODAY()),"Overdue",IF(Requests!M10-TODAY()<=Rules!$C$26,"Due Soon","On Track")) | T10: =IF(AND(G10="Pass",J10<>"Fail",L10="Pass",N10="Pass",P10<>"Fail"),"Approved",IF(OR(L10="Fail – Missing FOS",N10="Fail"),"Escalate","Needs Correction")) | U10: =IFERROR(IF(G10<>"Pass","Insufficient learning objectives; ","")&IF(AND(J10="Fail",D10="Group"),"Missing attendance checks; ","")&IF(L10<>"Pass","Missing field of study; ","")&IF(N10<>"Pass","Invalid program level; ","")&IF(AND(P10="Fail",D10="Self-study"),"Insufficient review questions; ",""),"Check data")
A11: =Requests!A11 | B11: =Requests!B11 | C11: =Requests!F11 | D11: =Requests!E11 | E11: =Requests!I11 | F11: =ROUNDUP(C11/50*Rules!$C$5,0) | G11: =IF(E11>=F11,"Pass","Fail") | H11: =Requests!J11 | I11: =IF(D11="Group",ROUNDUP(C11/50*Rules!$C$9,0),0) | J11: =IF(D11="Self-study","N/A",IF(H11>=I11,"Pass","Fail")) | K11: =Requests!G11 | L11: =IF(K11<>"","Pass","Fail – Missing FOS") | M11: =Requests!H11 | N11: =IF(OR(M11="Basic",M11="Intermediate",M11="Advanced"),"Pass","Fail") | O11: =Requests!K11 | P11: =IF(D11="Self-study",IF(O11>=ROUNDUP(Q11*Rules!$C$12,0),"Pass","Fail"),"N/A") | Q11: =IF(C11<25,0,FLOOR(C11/50,0.5)) | R11: =IF(C11<50,0,ROUNDDOWN(C11/50*5,0)/5) | S11: =IF(AND(Requests!O11<>"Approved",Requests!M11<TODAY()),"Overdue",IF(Requests!M11-TODAY()<=Rules!$C$26,"Due Soon","On Track")) | T11: =IF(AND(G11="Pass",J11<>"Fail",L11="Pass",N11="Pass",P11<>"Fail"),"Approved",IF(OR(L11="Fail – Missing FOS",N11="Fail"),"Escalate","Needs Correction")) | U11: =IFERROR(IF(G11<>"Pass","Insufficient learning objectives; ","")&IF(AND(J11="Fail",D11="Group"),"Missing attendance checks; ","")&IF(L11<>"Pass","Missing field of study; ","")&IF(N11<>"Pass","Invalid program level; ","")&IF(AND(P11="Fail",D11="Self-study"),"Insufficient review questions; ",""),"Check data")
A12: =Requests!A12 | B12: =Requests!B12 | C12: =Requests!F12 | D12: =Requests!E12 | E12: =Requests!I12 | F12: =ROUNDUP(C12/50*Rules!$C$5,0) | G12: =IF(E12>=F12,"Pass","Fail") | H12: =Requests!J12 | I12: =IF(D12="Group",ROUNDUP(C12/50*Rules!$C$9,0),0) | J12: =IF(D12="Self-study","N/A",IF(H12>=I12,"Pass","Fail")) | K12: =Requests!G12 | L12: =IF(K12<>"","Pass","Fail – Missing FOS") | M12: =Requests!H12 | N12: =IF(OR(M12="Basic",M12="Intermediate",M12="Advanced"),"Pass","Fail") | O12: =Requests!K12 | P12: =IF(D12="Self-study",IF(O12>=ROUNDUP(Q12*Rules!$C$12,0),"Pass","Fail"),"N/A") | Q12: =IF(C12<25,0,FLOOR(C12/50,0.5)) | R12: =IF(C12<50,0,ROUNDDOWN(C12/50*5,0)/5) | S12: =IF(AND(Requests!O12<>"Approved",Requests!M12<TODAY()),"Overdue",IF(Requests!M12-TODAY()<=Rules!$C$26,"Due Soon","On Track")) | T12: =IF(AND(G12="Pass",J12<>"Fail",L12="Pass",N12="Pass",P12<>"Fail"),"Approved",IF(OR(L12="Fail – Missing FOS",N12="Fail"),"Escalate","Needs Correction")) | U12: =IFERROR(IF(G12<>"Pass","Insufficient learning objectives; ","")&IF(AND(J12="Fail",D12="Group"),"Missing attendance checks; ","")&IF(L12<>"Pass","Missing field of study; ","")&IF(N12<>"Pass","Invalid program level; ","")&IF(AND(P12="Fail",D12="Self-study"),"Insufficient review questions; ",""),"Check data")
A13: =Requests!A13 | B13: =Requests!B13 | C13: =Requests!F13 | D13: =Requests!E13 | E13: =Requests!I13 | F13: =ROUNDUP(C13/50*Rules!$C$5,0) | G13: =IF(E13>=F13,"Pass","Fail") | H13: =Requests!J13 | I13: =IF(D13="Group",ROUNDUP(C13/50*Rules!$C$9,0),0) | J13: =IF(D13="Self-study","N/A",IF(H13>=I13,"Pass","Fail")) | K13: =Requests!G13 | L13: =IF(K13<>"","Pass","Fail – Missing FOS") | M13: =Requests!H13 | N13: =IF(OR(M13="Basic",M13="Intermediate",M13="Advanced"),"Pass","Fail") | O13: =Requests!K13 | P13: =IF(D13="Self-study",IF(O13>=ROUNDUP(Q13*Rules!$C$12,0),"Pass","Fail"),"N/A") | Q13: =IF(C13<25,0,FLOOR(C13/50,0.5)) | R13: =IF(C13<50,0,ROUNDDOWN(C13/50*5,0)/5) | S13: =IF(AND(Requests!O13<>"Approved",Requests!M13<TODAY()),"Overdue",IF(Requests!M13-TODAY()<=Rules!$C$26,"Due Soon","On Track")) | T13: =IF(AND(G13="Pass",J13<>"Fail",L13="Pass",N13="Pass",P13<>"Fail"),"Approved",IF(OR(L13="Fail – Missing FOS",N13="Fail"),"Escalate","Needs Correction")) | U13: =IFERROR(IF(G13<>"Pass","Insufficient learning objectives; ","")&IF(AND(J13="Fail",D13="Group"),"Missing attendance checks; ","")&IF(L13<>"Pass","Missing field of study; ","")&IF(N13<>"Pass","Invalid program level; ","")&IF(AND(P13="Fail",D13="Self-study"),"Insufficient review questions; ",""),"Check data")
... A101: =Requests!A101 | B101: =Requests!B101 | C101: =Requests!F101 | D101: =Requests!E101 | E101: =Requests!I101 | F101: =ROUNDUP(C101/50*Rules!$C$5,0) | G101: =IF(E101>=F101,"Pass","Fail") | H101: =Requests!J101 | I101: =IF(D101="Group",ROUNDUP(C101/50*Rules!$C$9,0),0) | J101: =IF(D101="Self-study","N/A",IF(H101>=I101,"Pass","Fail")) | K101: =Requests!G101 | L101: =IF(K101<>"","Pass","Fail – Missing FOS") | M101: =Requests!H101 | N101: =IF(OR(M101="Basic",M101="Intermediate",M101="Advanced"),"Pass","Fail") | O101: =Requests!K101 | P101: =IF(D101="Self-study",IF(O101>=ROUNDUP(Q101*Rules!$C$12,0),"Pass","Fail"),"N/A") | Q101: =IF(C101<25,0,FLOOR(C101/50,0.5)) | R101: =IF(C101<50,0,ROUNDDOWN(C101/50*5,0)/5) | S101: =IF(AND(Requests!O101<>"Approved",Requests!M101<TODAY()),"Overdue",IF(Requests!M101-TODAY()<=Rules!$C$26,"Due Soon","On Track")) | T101: =IF(AND(G101="Pass",J101<>"Fail",L101="Pass",N101="Pass",P101<>"Fail"),"Approved",IF(OR(L101="Fail – Missing FOS",N101="Fail"),"Escalate","Needs Correction")) | U101: =IFERROR(IF(G101<>"Pass","Insufficient learning objectives; ","")&IF(AND(J101="Fail",D101="Group"),"Missing attendance checks; ","")&IF(L101<>"Pass","Missing field of study; ","")&IF(N101<>"Pass","Invalid program level; ","")&IF(AND(P101="Fail",D101="Self-study"),"Insufficient review questions; ",""),"Check data")

Sheet Credit Calculator
A1: Request ID | B1: Course Title | C1: Duration (min) | D1: Credits (Half-Credit Rounding) | E1: Credits (Fifth-Credit Rounding) | F1: Min Learning Objectives | G1: Rounding Method | H1: Credit Flag | J1: Formula Reference | K1: Formula | L1: Description
A2: =Requests!A2 | B2: =Requests!B2 | C2: =Requests!F2 | D2: =IF(C2<25,0,FLOOR(C2/50,Rules!$C$15)) | E2: =IF(C2<50,0,ROUNDDOWN(C2/50*5,0)/5) | F2: =ROUNDUP(C2/50*Rules!$C$5,0) | G2: =IF(Requests!E2="Group","Half-Credit","Fifth-Credit") | H2: =IF(C2<25,"Flag: < 25 min – no credit",IF(C2<50,"Flag: verify min duration","OK")) | J2: Half-Credit Formula | K2: =IF(F<25,0,FLOOR(F/50,0.5)) | L2: Rounds down to nearest 0.5 credit; awards 0 if < 25 min
A3: =Requests!A3 | B3: =Requests!B3 | C3: =Requests!F3 | D3: =IF(C3<25,0,FLOOR(C3/50,Rules!$C$15)) | E3: =IF(C3<50,0,ROUNDDOWN(C3/50*5,0)/5) | F3: =ROUNDUP(C3/50*Rules!$C$5,0) | G3: =IF(Requests!E3="Group","Half-Credit","Fifth-Credit") | H3: =IF(C3<25,"Flag: < 25 min – no credit",IF(C3<50,"Flag: verify min duration","OK")) | J3: Fifth-Credit Formula | K3: =IF(F<50,0,ROUNDDOWN(F/50*5,0)/5) | L3: Rounds down to nearest 0.2 credit; awards 0 if < 50 min
A4: =Requests!A4 | B4: =Requests!B4 | C4: =Requests!F4 | D4: =IF(C4<25,0,FLOOR(C4/50,Rules!$C$15)) | E4: =IF(C4<50,0,ROUNDDOWN(C4/50*5,0)/5) | F4: =ROUNDUP(C4/50*Rules!$C$5,0) | G4: =IF(Requests!E4="Group","Half-Credit","Fifth-Credit") | H4: =IF(C4<25,"Flag: < 25 min – no credit",IF(C4<50,"Flag: verify min duration","OK"))
A5: =Requests!A5 | B5: =Requests!B5 | C5: =Requests!F5 | D5: =IF(C5<25,0,FLOOR(C5/50,Rules!$C$15)) | E5: =IF(C5<50,0,ROUNDDOWN(C5/50*5,0)/5) | F5: =ROUNDUP(C5/50*Rules!$C$5,0) | G5: =IF(Requests!E5="Group","Half-Credit","Fifth-Credit") | H5: =IF(C5<25,"Flag: < 25 min – no credit",IF(C5<50,"Flag: verify min duration","OK"))
A6: =Requests!A6 | B6: =Requests!B6 | C6: =Requests!F6 | D6: =IF(C6<25,0,FLOOR(C6/50,Rules!$C$15)) | E6: =IF(C6<50,0,ROUNDDOWN(C6/50*5,0)/5) | F6: =ROUNDUP(C6/50*Rules!$C$5,0) | G6: =IF(Requests!E6="Group","Half-Credit","Fifth-Credit") | H6: =IF(C6<25,"Flag: < 25 min – no credit",IF(C6<50,"Flag: verify min duration","OK"))
A7: =Requests!A7 | B7: =Requests!B7 | C7: =Requests!F7 | D7: =IF(C7<25,0,FLOOR(C7/50,Rules!$C$15)) | E7: =IF(C7<50,0,ROUNDDOWN(C7/50*5,0)/5) | F7: =ROUNDUP(C7/50*Rules!$C$5,0) | G7: =IF(Requests!E7="Group","Half-Credit","Fifth-Credit") | H7: =IF(C7<25,"Flag: < 25 min – no credit",IF(C7<50,"Flag: verify min duration","OK"))
A8: =Requests!A8 | B8: =Requests!B8 | C8: =Requests!F8 | D8: =IF(C8<25,0,FLOOR(C8/50,Rules!$C$15)) | E8: =IF(C8<50,0,ROUNDDOWN(C8/50*5,0)/5) | F8: =ROUNDUP(C8/50*Rules!$C$5,0) | G8: =IF(Requests!E8="Group","Half-Credit","Fifth-Credit") | H8: =IF(C8<25,"Flag: < 25 min – no credit",IF(C8<50,"Flag: verify min duration","OK"))
A9: =Requests!A9 | B9: =Requests!B9 | C9: =Requests!F9 | D9: =IF(C9<25,0,FLOOR(C9/50,Rules!$C$15)) | E9: =IF(C9<50,0,ROUNDDOWN(C9/50*5,0)/5) | F9: =ROUNDUP(C9/50*Rules!$C$5,0) | G9: =IF(Requests!E9="Group","Half-Credit","Fifth-Credit") | H9: =IF(C9<25,"Flag: < 25 min – no credit",IF(C9<50,"Flag: verify min duration","OK"))
A10: =Requests!A10 | B10: =Requests!B10 | C10: =Requests!F10 | D10: =IF(C10<25,0,FLOOR(C10/50,Rules!$C$15)) | E10: =IF(C10<50,0,ROUNDDOWN(C10/50*5,0)/5) | F10: =ROUNDUP(C10/50*Rules!$C$5,0) | G10: =IF(Requests!E10="Group","Half-Credit","Fifth-Credit") | H10: =IF(C10<25,"Flag: < 25 min – no credit",IF(C10<50,"Flag: verify min duration","OK"))
A11: =Requests!A11 | B11: =Requests!B11 | C11: =Requests!F11 | D11: =IF(C11<25,0,FLOOR(C11/50,Rules!$C$15)) | E11: =IF(C11<50,0,ROUNDDOWN(C11/50*5,0)/5) | F11: =ROUNDUP(C11/50*Rules!$C$5,0) | G11: =IF(Requests!E11="Group","Half-Credit","Fifth-Credit") | H11: =IF(C11<25,"Flag: < 25 min – no credit",IF(C11<50,"Flag: verify min duration","OK"))
A12: =Requests!A12 | B12: =Requests!B12 | C12: =Requests!F12 | D12: =IF(C12<25,0,FLOOR(C12/50,Rules!$C$15)) | E12: =IF(C12<50,0,ROUNDDOWN(C12/50*5,0)/5) | F12: =ROUNDUP(C12/50*Rules!$C$5,0) | G12: =IF(Requests!E12="Group","Half-Credit","Fifth-Credit") | H12: =IF(C12<25,"Flag: < 25 min – no credit",IF(C12<50,"Flag: verify min duration","OK"))
A13: =Requests!A13 | B13: =Requests!B13 | C13: =Requests!F13 | D13: =IF(C13<25,0,FLOOR(C13/50,Rules!$C$15)) | E13: =IF(C13<50,0,ROUNDDOWN(C13/50*5,0)/5) | F13: =ROUNDUP(C13/50*Rules!$C$5,0) | G13: =IF(Requests!E13="Group","Half-Credit","Fifth-Credit") | H13: =IF(C13<25,"Flag: < 25 min – no credit",IF(C13<50,"Flag: verify min duration","OK"))
A14: =Requests!A14 | B14: =Requests!B14 | C14: =Requests!F14 | D14: =IF(C14<25,0,FLOOR(C14/50,Rules!$C$15)) | E14: =IF(C14<50,0,ROUNDDOWN(C14/50*5,0)/5) | F14: =ROUNDUP(C14/50*Rules!$C$5,0) | G14: =IF(Requests!E14="Group","Half-Credit","Fifth-Credit") | H14: =IF(C14<25,"Flag: < 25 min – no credit",IF(C14<50,"Flag: verify min duration","OK"))
A15: =Requests!A15 | B15: =Requests!B15 | C15: =Requests!F15 | D15: =IF(C15<25,0,FLOOR(C15/50,Rules!$C$15)) | E15: =IF(C15<50,0,ROUNDDOWN(C15/50*5,0)/5) | F15: =ROUNDUP(C15/50*Rules!$C$5,0) | G15: =IF(Requests!E15="Group","Half-Credit","Fifth-Credit") | H15: =IF(C15<25,"Flag: < 25 min – no credit",IF(C15<50,"Flag: verify min duration","OK"))
... A101: =Requests!A101 | B101: =Requests!B101 | C101: =Requests!F101 | D101: =IF(C101<25,0,FLOOR(C101/50,Rules!$C$15)) | E101: =IF(C101<50,0,ROUNDDOWN(C101/50*5,0)/5) | F101: =ROUNDUP(C101/50*Rules!$C$5,0) | G101: =IF(Requests!E101="Group","Half-Credit","Fifth-Credit") | H101: =IF(C101<25,"Flag: < 25 min – no credit",IF(C101<50,"Flag: verify min duration","OK"))

Sheet SLA Monitor
A1: Request ID | B1: Course Title | C1: Instructor | D1: Submitted Date | E1: SLA Due Date | F1: Days Until Due | G1: Status | H1: SLA Flag | I1: Reviewer
A2: =Requests!A2 | B2: =Requests!B2 | C2: =Requests!C2 | D2: =Requests!D2 | E2: =Requests!M2 | F2: =Requests!M2-TODAY() | G2: =Requests!O2 | H2: =IF(AND(G2<>"Approved",E2<TODAY()),"Overdue",IF(AND(G2<>"Approved",E2-TODAY()<=Rules!$C$26),"Due Soon","On Track")) | I2: =Requests!N2
A3: =Requests!A3 | B3: =Requests!B3 | C3: =Requests!C3 | D3: =Requests!D3 | E3: =Requests!M3 | F3: =Requests!M3-TODAY() | G3: =Requests!O3 | H3: =IF(AND(G3<>"Approved",E3<TODAY()),"Overdue",IF(AND(G3<>"Approved",E3-TODAY()<=Rules!$C$26),"Due Soon","On Track")) | I3: =Requests!N3
A4: =Requests!A4 | B4: =Requests!B4 | C4: =Requests!C4 | D4: =Requests!D4 | E4: =Requests!M4 | F4: =Requests!M4-TODAY() | G4: =Requests!O4 | H4: =IF(AND(G4<>"Approved",E4<TODAY()),"Overdue",IF(AND(G4<>"Approved",E4-TODAY()<=Rules!$C$26),"Due Soon","On Track")) | I4: =Requests!N4
A5: =Requests!A5 | B5: =Requests!B5 | C5: =Requests!C5 | D5: =Requests!D5 | E5: =Requests!M5 | F5: =Requests!M5-TODAY() | G5: =Requests!O5 | H5: =IF(AND(G5<>"Approved",E5<TODAY()),"Overdue",IF(AND(G5<>"Approved",E5-TODAY()<=Rules!$C$26),"Due Soon","On Track")) | I5: =Requests!N5
A6: =Requests!A6 | B6: =Requests!B6 | C6: =Requests!C6 | D6: =Requests!D6 | E6: =Requests!M6 | F6: =Requests!M6-TODAY() | G6: =Requests!O6 | H6: =IF(AND(G6<>"Approved",E6<TODAY()),"Overdue",IF(AND(G6<>"Approved",E6-TODAY()<=Rules!$C$26),"Due Soon","On Track")) | I6: =Requests!N6
A7: =Requests!A7 | B7: =Requests!B7 | C7: =Requests!C7 | D7: =Requests!D7 | E7: =Requests!M7 | F7: =Requests!M7-TODAY() | G7: =Requests!O7 | H7: =IF(AND(G7<>"Approved",E7<TODAY()),"Overdue",IF(AND(G7<>"Approved",E7-TODAY()<=Rules!$C$26),"Due Soon","On Track")) | I7: =Requests!N7
A8: =Requests!A8 | B8: =Requests!B8 | C8: =Requests!C8 | D8: =Requests!D8 | E8: =Requests!M8 | F8: =Requests!M8-TODAY() | G8: =Requests!O8 | H8: =IF(AND(G8<>"Approved",E8<TODAY()),"Overdue",IF(AND(G8<>"Approved",E8-TODAY()<=Rules!$C$26),"Due Soon","On Track")) | I8: =Requests!N8
A9: =Requests!A9 | B9: =Requests!B9 | C9: =Requests!C9 | D9: =Requests!D9 | E9: =Requests!M9 | F9: =Requests!M9-TODAY() | G9: =Requests!O9 | H9: =IF(AND(G9<>"Approved",E9<TODAY()),"Overdue",IF(AND(G9<>"Approved",E9-TODAY()<=Rules!$C$26),"Due Soon","On Track")) | I9: =Requests!N9
A10: =Requests!A10 | B10: =Requests!B10 | C10: =Requests!C10 | D10: =Requests!D10 | E10: =Requests!M10 | F10: =Requests!M10-TODAY() | G10: =Requests!O10 | H10: =IF(AND(G10<>"Approved",E10<TODAY()),"Overdue",IF(AND(G10<>"Approved",E10-TODAY()<=Rules!$C$26),"Due Soon","On Track")) | I10: =Requests!N10
A11: =Requests!A11 | B11: =Requests!B11 | C11: =Requests!C11 | D11: =Requests!D11 | E11: =Requests!M11 | F11: =Requests!M11-TODAY() | G11: =Requests!O11 | H11: =IF(AND(G11<>"Approved",E11<TODAY()),"Overdue",IF(AND(G11<>"Approved",E11-TODAY()<=Rules!$C$26),"Due Soon","On Track")) | I11: =Requests!N11
A12: =Requests!A12 | B12: =Requests!B12 | C12: =Requests!C12 | D12: =Requests!D12 | E12: =Requests!M12 | F12: =Requests!M12-TODAY() | G12: =Requests!O12 | H12: =IF(AND(G12<>"Approved",E12<TODAY()),"Overdue",IF(AND(G12<>"Approved",E12-TODAY()<=Rules!$C$26),"Due Soon","On Track")) | I12: =Requests!N12
A13: =Requests!A13 | B13: =Requests!B13 | C13: =Requests!C13 | D13: =Requests!D13 | E13: =Requests!M13 | F13: =Requests!M13-TODAY() | G13: =Requests!O13 | H13: =IF(AND(G13<>"Approved",E13<TODAY()),"Overdue",IF(AND(G13<>"Approved",E13-TODAY()<=Rules!$C$26),"Due Soon","On Track")) | I13: =Requests!N13
... A101: =Requests!A101 | B101: =Requests!B101 | C101: =Requests!C101 | D101: =Requests!D101 | E101: =Requests!M101 | F101: =Requests!M101-TODAY() | G101: =Requests!O101 | H101: =IF(AND(G101<>"Approved",E101<TODAY()),"Overdue",IF(AND(G101<>"Approved",E101-TODAY()<=Rules!$C$26),"Due Soon","On Track")) | I101: =Requests!N101

Sheet Dashboard
A1: 📊 CPE Analyst Desk – Dashboard
A3: KEY PERFORMANCE INDICATORS
A4: Total Submissions | B4: Approved | C4: Needs Correction | D4: Escalated | E4: Pending | F4: Overdue
A5: =COUNTA(Requests!A2:A101) | B5: =COUNTIF(Requests!O2:O101,"Approved") | C5: =COUNTIF(Requests!O2:O101,"Needs Correction") | D5: =COUNTIF(Requests!O2:O101,"Escalate") | E5: =COUNTIF(Requests!O2:O101,"Pending") | F5: =COUNTIF('SLA Monitor'!H2:H101,"Overdue")
A7: Requests by Status
A8: Status | B8: Count | C8: % of Total
A9: Approved | B9: =COUNTIF(Requests!O2:O101,"Approved") | C9: =B9/COUNTA(Requests!A2:A101)
A10: Needs Correction | B10: =COUNTIF(Requests!O2:O101,"Needs Correction") | C10: =B10/COUNTA(Requests!A2:A101)
A11: Escalate | B11: =COUNTIF(Requests!O2:O101,"Escalate") | C11: =B11/COUNTA(Requests!A2:A101)
A12: Pending | B12: =COUNTIF(Requests!O2:O101,"Pending") | C12: =B12/COUNTA(Requests!A2:A101)
A14: Top Rejection Reasons
A15: Rejection Reason | B15: Count | C15: % of Non-Approved | D15: =COUNTIF(Requests!O2:O101,"<>Approved")
A16: Missing Learning Objectives | B16: =COUNTIF(Review!U2:U101,"*learning objectives*") | C16: =IFERROR(B16/$D$15,0)
A17: Missing Attendance Checks | B17: =COUNTIF(Review!U2:U101,"*attendance*") | C17: =IFERROR(B17/$D$15,0)
A18: Missing Field of Study | B18: =COUNTIF(Review!U2:U101,"*field of study*") | C18: =IFERROR(B18/$D$15,0)
A19: Insufficient Review Qs | B19: =COUNTIF(Review!U2:U101,"*review questions*") | C19: =IFERROR(B19/$D$15,0)
A20: Invalid Program Level | B20: =COUNTIF(Review!U2:U101,"*program level*") | C20: =IFERROR(B20/$D$15,0)
A22: Reviewer Workload
A23: Reviewer | B23: Assigned | C23: Approved | D23: Pending/Open
A24: CPE Desk - Priya | B24: =COUNTIF(Requests!N2:N101,"CPE Desk - Priya") | C24: =COUNTIFS(Requests!N2:N101,"CPE Desk - Priya",Requests!O2:O101,"Approved") | D24: =B24-C24
A25: CPE Desk - Omar | B25: =COUNTIF(Requests!N2:N101,"CPE Desk - Omar") | C25: =COUNTIFS(Requests!N2:N101,"CPE Desk - Omar",Requests!O2:O101,"Approved") | D25: =B25-C25
A26: CPE Desk - Sarah | B26: =COUNTIF(Requests!N2:N101,"CPE Desk - Sarah") | C26: =COUNTIFS(Requests!N2:N101,"CPE Desk - Sarah",Requests!O2:O101,"Approved") | D26: =B26-C26
A27: CPE Desk - Luis | B27: =COUNTIF(Requests!N2:N101,"CPE Desk - Luis") | C27: =COUNTIFS(Requests!N2:N101,"CPE Desk - Luis",Requests!O2:O101,"Approved") | D27: =B27-C27
A29: Avg Turnaround (days, est.) | B29: =AVERAGEIF(Requests!O2:O101,"Approved",Requests!M2:M101)-AVERAGEIF(Requests!O2:O101,"Approved",Requests!D2:D101)

Sheet Certificates
A1: Certificate No | B1: Learner Name | C1: Course Title | D1: Instructor | E1: Completion Date | F1: Credits Earned | G1: Field of Study | H1: Program Level | I1: Delivery Method | J1: Certificate Issued By | K1: Issue Date
A2: This sheet auto-populates from approved rows via the macro below. For full mail-merge, link this sheet as the Word data source.
A3: CERT-2026-001 | B3: Participant – Karen's Session | C3: Mastering Blockchain in Accounting | D3: Karen Li | E3: 19-Sep-2026 | F3: 2.5 | G3: Economics | H3: Basic | I3: Self-study | J3: CPE Desk, Firm Name | K3: 29-Oct-2026
A4: CERT-2026-002 | B4: Participant – Karen's Session | C4: Mastering Blockchain in Accounting | D4: Karen Li | E4: 22-Sep-2026 | F4: 2.5 | G4: Management | H4: Basic | I4: Self-study | J4: CPE Desk, Firm Name | K4: 29-Oct-2026
A5: CERT-2026-003 | B5: Participant – Elena's Session | C5: Introduction to Tax Reform | D5: Elena Voss | E5: 16-Oct-2026 | F5: 3 | G5: Specialized Knowledge | H5: Basic | I5: Group | J5: CPE Desk, Firm Name | K5: 29-Oct-2026
A6: CERT-2026-004 | B6: Participant – Olivia's Session | C6: Workshop: Data Analytics for CPAs | D6: Olivia Chen | E6: 06-Sep-2026 | F6: 1 | G6: Business Law | H6: Basic | I6: Self-study | J6: CPE Desk, Firm Name | K6: 29-Oct-2026
A7: CERT-2026-005 | B7: Participant – Frank's Session | C7: Practical International Tax | D7: Frank Huang | E7: 10-Oct-2026 | F7: 2 | G7: Economics | H7: Basic | I7: Group | J7: CPE Desk, Firm Name | K7: 29-Oct-2026
A8: CERT-2026-006 | B8: Participant – Frank's Session | C8: Seminar: Financial Modeling | D8: Frank Huang | E8: 22-Sep-2026 | F8: 1 | G8: Business Law | H8: Advanced | I8: Self-study | J8: CPE Desk, Firm Name | K8: 29-Oct-2026
A9: CERT-2026-007 | B9: Participant – Rachel's Session | C9: Introduction to Blockchain in Accounting | D9: Rachel Novak | E9: 20-Sep-2026 | F9: 0 | G9: Auditing | H9: Advanced | I9: Group | J9: CPE Desk, Firm Name | K9: 29-Oct-2026
A10: CERT-2026-008 | B10: Participant – Karen's Session | C10: Advanced Revenue Recognition | D10: Karen Li | E10: 10-Sep-2026 | F10: 1.5 | G10: Economics | H10: Basic | I10: Group | J10: CPE Desk, Firm Name | K10: 29-Oct-2026
A11: CERT-2026-009 | B11: Participant – Ben's Session | C11: Introduction to Tax Reform | D11: Ben Tanaka | E11: 01-Oct-2026 | F11: 0.5 | G11: Finance | H11: Basic | I11: Self-study | J11: CPE Desk, Firm Name | K11: 29-Oct-2026
A12: CERT-2026-010 | B12: Participant – Frank's Session | C12: Practical Auditing Standards | D12: Frank Huang | E12: 23-Sep-2026 | F12: 1.5 | G12: Auditing | H12: Intermediate | I12: Self-study | J12: CPE Desk, Firm Name | K12: 29-Oct-2026
A13: CERT-2026-011 | B13: Participant – Clara's Session | C13: Foundations of GAAP Updates | D13: Clara Singh | E13: 24-Oct-2026 | F13: 1 | G13: Information Technology | H13: Intermediate | I13: Group | J13: CPE Desk, Firm Name | K13: 29-Oct-2026
A14: CERT-2026-012 | B14: Participant – Frank's Session | C14: Workshop: Revenue Recognition | D14: Frank Huang | E14: 30-Sep-2026 | F14: 2.5 | G14: Ethics | H14: Intermediate | I14: Group | J14: CPE Desk, Firm Name | K14: 29-Oct-2026
... A60: CERT-2026-058 | B60: Participant – Clara's Session | C60: Deep Dive into Cybersecurity Risk | D60: Clara Singh | E60: 24-Sep-2026 | F60: 3 | G60: Taxation | H60: Basic | I60: Self-study | J60: CPE Desk, Firm Name | K60: 29-Oct-2026

Sheet Email Templates
A1: CPE DESK – EMAIL TEMPLATES
A2: 1. MISSING INFORMATION
A3: Subject | B3: CPE Request [Request ID] – Additional Information Required
A4: Body | B4: Dear [Instructor Name], Thank you for submitting [Course Title] (Request ID: [Request ID]) on [Submitted Date]. During our review, we identified the following items that require clarification or completion before we can process your CPE credit request: • [List missing items, e.g., Field of Study not specified] • [Learning objectives provided: X; minimum required: Y] Please respond with the updated information by [SLA Due Date] to avoid delays. Regards, CPE Desk | [Reviewer Name] [Firm Name]
A5: 2. APPROVAL NOTICE
A6: Subject | B6: CPE Credits Approved – [Course Title] ([Request ID])
A7: Body | B7: Dear [Instructor Name], We are pleased to confirm that your CPE submission has been reviewed and approved. Course Title : [Course Title] Request ID : [Request ID] Credits : [Credits Earned] Field of Study: [Field of Study] Program Level: [Program Level] Certificates will be distributed to participants within 5 business days. Please retain this notice for your records. Regards, CPE Desk | [Reviewer Name] [Firm Name]
A8: 3. CORRECTION REQUEST
A9: Subject | B9: CPE Request [Request ID] – Correction Required
A10: Body | B10: Dear [Instructor Name], We have reviewed your CPE submission for [Course Title] (Request ID: [Request ID]). The following corrections are needed before we can approve this request: • [Specific correction, e.g., Increase learning objectives from X to Y] • [Specific correction, e.g., Add attendance verification records] Please resubmit the corrected materials by [SLA Due Date]. If you need assistance, please contact us at cpe-desk@firm.com. Regards, CPE Desk | [Reviewer Name] [Firm Name]
A11: 4. DELAY UPDATE
A12: Subject | B12: CPE Request [Request ID] – Processing Update
A13: Body | B13: Dear [Instructor Name], We wanted to provide you with an update on your CPE request for [Course Title] (Request ID: [Request ID]). Your submission is currently under review. Due to [reason for delay], we anticipate completing our review by [new estimated date]. We apologise for any inconvenience this may cause. If you have any urgent concerns, please reply to this email or call [phone number]. Regards, CPE Desk | [Reviewer Name] [Firm Name]
A14: 5. COMPLAINT REPLY
A15: Subject | B15: RE: Your Concern Regarding CPE Request [Request ID]
A16: Body | B16: Dear [Learner/Instructor Name], Thank you for bringing your concern to our attention. We take all feedback seriously. We have reviewed Request ID [Request ID] and understand your frustration regarding [brief description of the complaint]. After investigation, we have determined that [explanation/resolution]. [If applicable: We have made the necessary adjustments and the corrected record/certificate will be issued by [date].] Please do not hesitate to contact us if you have any further questions. Regards, CPE Desk | Senior Reviewer [Firm Name]

Sheet Test Cases
A1: Test # | B1: Duration (min) | C1: Delivery Method | D1: Expected Credits (Half) | E1: Expected Credits (Fifth) | F1: Formula (Half) | G1: Formula (Fifth) | H1: Actual (Half) | I1: Actual (Fifth) | J1: Pass/Fail
A2: 1 | B2: 75 | C2: Group | D2: 1.5 | E2: 1.4 | F2: FLOOR(75/50,0.5)=1.5 | G2: ROUNDDOWN(75/50*5,0)/5=1.4 | H2: 1.5 | I2: 1.4 | J2: PASS
A3: 2 | B3: 140 | C3: Group | D3: 2.5 | E3: 2.8 | F3: FLOOR(140/50,0.5)=2.5 | G3: ROUNDDOWN(140/50*5,0)/5=2.8 | H3: 2.5 | I3: 2.8 | J3: PASS
A4: 3 | B4: 60 | C4: Group | D4: 1 | E4: 1.2 | F4: FLOOR(60/50,0.5)=1.0 | G4: ROUNDDOWN(60/50*5,0)/5=1.2 | H4: 1 | I4: 1.2 | J4: PASS
A5: 4 | B5: 49 | C5: Group | D5: 0.5 | E5: 0 | F5: FLOOR(49/50,0.5)=0.5 | G5: IF<50 -> 0 (fifth-credit needs >=50) | H5: 0.5 | I5: 0 | J5: PASS
A6: 5 | B6: 20 | C6: Group | D6: 0 | E6: 0 | F6: IF<25 -> 0; FLAG | G6: IF<50 -> 0; FLAG | H6: 0 | I6: 0 | J6: PASS
A7: 6 | B7: 100 | C7: Group | D7: 2 | E7: 2 | F7: FLOOR(100/50,0.5)=2.0 | G7: ROUNDDOWN(100/50*5,0)/5=2.0 | H7: 2 | I7: 2 | J7: PASS
A8: 7 | B8: 25 | C8: Group | D8: 0.5 | E8: 0 | F8: FLOOR(25/50,0.5)=0.5 | G8: IF<50 -> 0 | H8: 0.5 | I8: 0 | J8: PASS
A9: 8 | B9: 50 | C9: Self-study | D9: 1 | E9: 1 | F9: FLOOR(50/50,0.5)=1.0 | G9: ROUNDDOWN(50/50*5,0)/5=1.0 | H9: 1 | I9: 1 | J9: PASS
A10: 9 | B10: 150 | C10: Group | D10: 3 | E10: 3 | F10: FLOOR(150/50,0.5)=3.0 | G10: ROUNDDOWN(150/50*5,0)/5=3.0 | H10: 3 | I10: 3 | J10: PASS
A11: 10 | B11: 200 | C11: Group | D11: 4 | E11: 4 | F11: FLOOR(200/50,0.5)=4.0 | G11: ROUNDDOWN(200/50*5,0)/5=4.0 | H11: 4 | I11: 4 | J11: PASS
A13: Notes: Fifth-credit formula requires min 50 min (no credit below 50 min). Half-credit formula requires min 25 min. Test case 4 (49 min): half-credit = 0.5 under revised NASBA standards; fifth-credit = 0 (< 50 min threshold).

Sheet SOP
A1: CPE ANALYST DESK – STANDARD OPERATING PROCEDURE
A2: Version 1.0 | Effective: November 2026 | Owner: CPE Desk
A4: 1. PURPOSE
A5: To ensure all Continuing Professional Education (CPE) credit requests are reviewed, calculated, recorded, and communicated within established SLAs and in accordance with NASBA-style standards.
A7: 2. SCOPE
A8: All CPE submissions received from instructors, training coordinators, and third-party providers for webinars, classroom sessions, and e-learning programs.
A10: 3. ROLES & RESPONSIBILITIES
A11: CPE Analyst | Primary reviewer; completes initial review within 5 business days.
A12: Senior Reviewer | Handles escalations, complaints, and edge cases.
A13: Instructor/Provider | Submits requests; responds to correction notices.
A15: 4. PROCESS STEPS
A16: Step 1 – Intake : Log submission in the Requests sheet with all required fields.
... A52: v1.0 Nov 2026 Initial release.
